2025-06-04 13:48:57,828 [WARNING] app [C:\Users\keisu\python\app.py:89 - home()] WARNING ログ
2025-06-04 13:48:57,829 [ERROR] app [C:\Users\keisu\python\app.py:90 - home()] ERROR ログ
2025-06-04 13:48:57,829 [CRITICAL] app [C:\Users\keisu\python\app.py:91 - home()] CRITICAL ログ
2025-06-04 13:49:45,875 [WARNING] app [C:\Users\keisu\python\app.py:89 - home()] WARNING ログ
2025-06-04 13:49:45,876 [ERROR] app [C:\Users\keisu\python\app.py:90 - home()] ERROR ログ
2025-06-04 13:49:45,876 [CRITICAL] app [C:\Users\keisu\python\app.py:91 - home()] CRITICAL ログ
2025-06-04 14:01:52,123 [WARNING] app [C:\Users\keisu\python\app.py:89 - home()] WARNING ログ
2025-06-04 14:01:52,123 [ERROR] app [C:\Users\keisu\python\app.py:90 - home()] ERROR ログ
2025-06-04 14:01:52,124 [CRITICAL] app [C:\Users\keisu\python\app.py:91 - home()] CRITICAL ログ
2025-06-04 14:10:14,867 [WARNING] app [C:\Users\keisu\python\app.py:89 - home()] WARNING ログ
2025-06-04 14:10:14,867 [ERROR] app [C:\Users\keisu\python\app.py:90 - home()] ERROR ログ
2025-06-04 14:10:14,867 [CRITICAL] app [C:\Users\keisu\python\app.py:91 - home()] CRITICAL ログ
2025-06-04 14:23:08,514 [WARNING] app [C:\Users\keisu\python\app.py:89 - home()] WARNING ログ
2025-06-04 14:23:08,514 [ERROR] app [C:\Users\keisu\python\app.py:90 - home()] ERROR ログ
2025-06-04 14:23:08,514 [CRITICAL] app [C:\Users\keisu\python\app.py:91 - home()] CRITICAL ログ
2025-06-04 14:30:27,048 [WARNING] app [C:\Users\keisu\python\app.py:89 - home()] WARNING ログ
2025-06-04 14:30:27,048 [ERROR] app [C:\Users\keisu\python\app.py:90 - home()] ERROR ログ
2025-06-04 14:30:27,048 [CRITICAL] app [C:\Users\keisu\python\app.py:91 - home()] CRITICAL ログ
2025-06-04 14:42:37,814 [WARNING] app [C:\Users\keisu\python\app.py:89 - home()] WARNING ログ
2025-06-04 14:42:37,815 [ERROR] app [C:\Users\keisu\python\app.py:90 - home()] ERROR ログ
2025-06-04 14:42:37,815 [CRITICAL] app [C:\Users\keisu\python\app.py:91 - home()] CRITICAL ログ
2025-06-04 16:01:04,692 [WARNING] app [C:\Users\keisu\python\app.py:89 - home()] WARNING ログ
2025-06-04 16:01:04,692 [ERROR] app [C:\Users\keisu\python\app.py:90 - home()] ERROR ログ
2025-06-04 16:01:04,692 [CRITICAL] app [C:\Users\keisu\python\app.py:91 - home()] CRITICAL ログ
2025-06-04 16:43:41,493 [WARNING] app [C:\Users\keisu\python\app.py:89 - home()] WARNING ログ
2025-06-04 16:43:41,493 [ERROR] app [C:\Users\keisu\python\app.py:90 - home()] ERROR ログ
2025-06-04 16:43:41,493 [CRITICAL] app [C:\Users\keisu\python\app.py:91 - home()] CRITICAL ログ
2025-06-05 11:04:51,758 [WARNING] app [C:\Users\keisu\python\app.py:89 - home()] WARNING ログ
2025-06-05 11:04:51,758 [ERROR] app [C:\Users\keisu\python\app.py:90 - home()] ERROR ログ
2025-06-05 11:04:51,758 [CRITICAL] app [C:\Users\keisu\python\app.py:91 - home()] CRITICAL ログ
2025-06-05 11:05:01,985 [WARNING] app [C:\Users\keisu\python\app.py:89 - home()] WARNING ログ
2025-06-05 11:05:01,986 [ERROR] app [C:\Users\keisu\python\app.py:90 - home()] ERROR ログ
2025-06-05 11:05:01,986 [CRITICAL] app [C:\Users\keisu\python\app.py:91 - home()] CRITICAL ログ
2025-06-05 11:30:38,471 [WARNING] app [C:\Users\keisu\python\app.py:89 - home()] WARNING ログ
2025-06-05 11:30:38,472 [ERROR] app [C:\Users\keisu\python\app.py:90 - home()] ERROR ログ
2025-06-05 11:30:38,472 [CRITICAL] app [C:\Users\keisu\python\app.py:91 - home()] CRITICAL ログ
2025-06-05 11:30:41,918 [WARNING] app [C:\Users\keisu\python\app.py:89 - home()] WARNING ログ
2025-06-05 11:30:41,918 [ERROR] app [C:\Users\keisu\python\app.py:90 - home()] ERROR ログ
2025-06-05 11:30:41,918 [CRITICAL] app [C:\Users\keisu\python\app.py:91 - home()] CRITICAL ログ
2025-06-06 10:38:28,673 [WARNING] app [C:\Users\keisu\python\app.py:89 - home()] WARNING ログ
2025-06-06 10:38:28,673 [ERROR] app [C:\Users\keisu\python\app.py:90 - home()] ERROR ログ
2025-06-06 10:38:28,673 [CRITICAL] app [C:\Users\keisu\python\app.py:91 - home()] CRITICAL ログ
2025-06-06 11:59:20,748 [WARNING] app [C:\Users\keisu\python\app.py:89 - home()] WARNING ログ
2025-06-06 11:59:20,748 [ERROR] app [C:\Users\keisu\python\app.py:90 - home()] ERROR ログ
2025-06-06 11:59:20,748 [CRITICAL] app [C:\Users\keisu\python\app.py:91 - home()] CRITICAL ログ
2025-06-06 13:56:19,601 [WARNING] app [C:\Users\keisu\python\app.py:89 - home()] WARNING ログ
2025-06-06 13:56:19,601 [ERROR] app [C:\Users\keisu\python\app.py:90 - home()] ERROR ログ
2025-06-06 13:56:19,601 [CRITICAL] app [C:\Users\keisu\python\app.py:91 - home()] CRITICAL ログ
2025-06-06 13:56:57,445 [WARNING] app [C:\Users\keisu\python\app.py:89 - home()] WARNING ログ
2025-06-06 13:56:57,445 [ERROR] app [C:\Users\keisu\python\app.py:90 - home()] ERROR ログ
2025-06-06 13:56:57,445 [CRITICAL] app [C:\Users\keisu\python\app.py:91 - home()] CRITICAL ログ
2025-06-06 14:08:13,009 [WARNING] app [C:\Users\keisu\python\app.py:89 - home()] WARNING ログ
2025-06-06 14:08:13,010 [ERROR] app [C:\Users\keisu\python\app.py:90 - home()] ERROR ログ
2025-06-06 14:08:13,010 [CRITICAL] app [C:\Users\keisu\python\app.py:91 - home()] CRITICAL ログ
2025-06-06 14:41:16,737 [WARNING] app [C:\Users\keisu\python\app.py:116 - home()] WARNING ログ
2025-06-06 14:41:16,737 [ERROR] app [C:\Users\keisu\python\app.py:117 - home()] ERROR ログ
2025-06-06 14:41:16,737 [CRITICAL] app [C:\Users\keisu\python\app.py:118 - home()] CRITICAL ログ
2025-06-06 16:38:24,907 [WARNING] app [C:\Users\keisu\python\app.py:117 - home()] WARNING ログ
2025-06-06 16:38:24,908 [ERROR] app [C:\Users\keisu\python\app.py:118 - home()] ERROR ログ
2025-06-06 16:38:24,908 [CRITICAL] app [C:\Users\keisu\python\app.py:119 - home()] CRITICAL ログ
2025-06-09 10:45:08,476 [WARNING] app [C:\Users\keisu\python\app.py:118 - home()] WARNING ログ
2025-06-09 10:45:08,477 [ERROR] app [C:\Users\keisu\python\app.py:119 - home()] ERROR ログ
2025-06-09 10:45:08,477 [CRITICAL] app [C:\Users\keisu\python\app.py:120 - home()] CRITICAL ログ
2025-06-09 11:26:15,454 [WARNING] app [C:\Users\keisu\python\app.py:118 - home()] WARNING ログ
2025-06-09 11:26:15,455 [ERROR] app [C:\Users\keisu\python\app.py:119 - home()] ERROR ログ
2025-06-09 11:26:15,455 [CRITICAL] app [C:\Users\keisu\python\app.py:120 - home()] CRITICAL ログ
2025-06-09 11:33:11,951 [WARNING] app [C:\Users\keisu\python\app.py:118 - home()] WARNING ログ
2025-06-09 11:33:11,951 [ERROR] app [C:\Users\keisu\python\app.py:119 - home()] ERROR ログ
2025-06-09 11:33:11,951 [CRITICAL] app [C:\Users\keisu\python\app.py:120 - home()] CRITICAL ログ
2025-06-09 13:02:41,858 [WARNING] app [C:\Users\keisu\python\app.py:118 - home()] WARNING ログ
2025-06-09 13:02:41,859 [ERROR] app [C:\Users\keisu\python\app.py:119 - home()] ERROR ログ
2025-06-09 13:02:41,859 [CRITICAL] app [C:\Users\keisu\python\app.py:120 - home()] CRITICAL ログ
2025-06-11 15:52:48,658 [ERROR] app [C:\Users\keisu\python\app.py:128 - wrapper()] 【skillsheet_input中にエラー発生】GET /skillsheet_input: {'code': '42501', 'details': None, 'hint': None, 'message': 'new row violates row-level security policy for table "skillsheet"'}
Traceback (most recent call last):
  File "C:\Users\keisu\python\app.py", line 125, in wrapper
    return func(*args, **kwargs)
  File "C:\Users\keisu\python\app.py", line 513, in skillsheet_input
    result = supabase.table("skillsheet").upsert(data).execute()
  File "C:\Users\keisu\AppData\Local\Programs\Python\Python313\Lib\site-packages\postgrest\_sync\request_builder.py", line 78, in execute
    raise APIError(r.json())
postgrest.exceptions.APIError: {'code': '42501', 'details': None, 'hint': None, 'message': 'new row violates row-level security policy for table "skillsheet"'}
2025-06-12 11:51:49,976 [WARNING] app [C:\Users\keisu\python\app.py:297 - update_password_form()] パスワード更新失敗: 弱いパスワード
2025-06-12 11:52:22,369 [WARNING] app [C:\Users\keisu\python\app.py:297 - update_password_form()] パスワード更新失敗: 弱いパスワード
2025-06-12 13:02:02,075 [WARNING] app [C:\Users\keisu\python\app.py:297 - update_password_form()] パスワード更新失敗: 弱いパスワード
2025-06-13 10:34:21,390 [WARNING] app [C:\Users\keisu\python\app.py:197 - login()] ログイン失敗: email=keisuke.tezuka.dd@gmail.com エラー: Invalid login credentials
2025-06-13 10:56:51,908 [WARNING] app [C:\Users\keisu\python\app.py:802 - create_pdf()] プロフィール未登録: user_id=4c5ba71b-b6f5-470d-aa79-5154b1227748
2025-06-13 11:07:39,309 [WARNING] app [C:\Users\keisu\python\app.py:802 - create_pdf()] プロフィール未登録: user_id=4c5ba71b-b6f5-470d-aa79-5154b1227748
2025-06-13 14:13:33,004 [WARNING] app [C:\Users\keisu\python\app.py:798 - create_pdf()] プロフィール未登録: user_id=4c5ba71b-b6f5-470d-aa79-5154b1227748
2025-06-13 14:15:58,301 [WARNING] app [C:\Users\keisu\python\app.py:798 - create_pdf()] プロフィール未登録: user_id=4c5ba71b-b6f5-470d-aa79-5154b1227748
2025-06-13 14:16:02,011 [WARNING] app [C:\Users\keisu\python\app.py:798 - create_pdf()] プロフィール未登録: user_id=4c5ba71b-b6f5-470d-aa79-5154b1227748
2025-06-13 14:35:40,319 [ERROR] app [C:\Users\keisu\python\app.py:1209 - create_pdf()] PDF作成中にエラー発生: user_id=4c5ba71b-b6f5-470d-aa79-5154b1227748 エラー='UTF-8'
Traceback (most recent call last):
  File "C:\Users\keisu\AppData\Local\Programs\Python\Python313\Lib\site-packages\reportlab\pdfbase\pdfmetrics.py", line 698, in getFont
    return _fonts[fontName]
           ~~~~~~^^^^^^^^^^
KeyError: 'UTF-8'

During handling of the above exception, another exception occurred:

Traceback (most recent call last):
  File "C:\Users\keisu\python\app.py", line 835, in create_pdf
    p.setFont("UTF-8", 16)
    ~~~~~~~~~^^^^^^^^^^^^^
  File "C:\Users\keisu\AppData\Local\Programs\Python\Python313\Lib\site-packages\reportlab\pdfgen\canvas.py", line 1737, in setFont
    font = pdfmetrics.getFont(self._fontname)
  File "C:\Users\keisu\AppData\Local\Programs\Python\Python313\Lib\site-packages\reportlab\pdfbase\pdfmetrics.py", line 700, in getFont
    return findFontAndRegister(fontName)
  File "C:\Users\keisu\AppData\Local\Programs\Python\Python313\Lib\site-packages\reportlab\pdfbase\pdfmetrics.py", line 682, in findFontAndRegister
    face = getTypeFace(fontName)
  File "C:\Users\keisu\AppData\Local\Programs\Python\Python313\Lib\site-packages\reportlab\pdfbase\pdfmetrics.py", line 639, in getTypeFace
    return _typefaces[faceName]
           ~~~~~~~~~~^^^^^^^^^^
KeyError: 'UTF-8'
2025-06-13 14:39:19,380 [ERROR] app [C:\Users\keisu\python\app.py:1209 - create_pdf()] PDF作成中にエラー発生: user_id=4c5ba71b-b6f5-470d-aa79-5154b1227748 エラー='UTF-8'
Traceback (most recent call last):
  File "C:\Users\keisu\AppData\Local\Programs\Python\Python313\Lib\site-packages\reportlab\pdfbase\pdfmetrics.py", line 698, in getFont
    return _fonts[fontName]
           ~~~~~~^^^^^^^^^^
KeyError: 'UTF-8'

During handling of the above exception, another exception occurred:

Traceback (most recent call last):
  File "C:\Users\keisu\python\app.py", line 835, in create_pdf
    p.setFont("UTF-8", 16)
    ~~~~~~~~~^^^^^^^^^^^^^
  File "C:\Users\keisu\AppData\Local\Programs\Python\Python313\Lib\site-packages\reportlab\pdfgen\canvas.py", line 1737, in setFont
    font = pdfmetrics.getFont(self._fontname)
  File "C:\Users\keisu\AppData\Local\Programs\Python\Python313\Lib\site-packages\reportlab\pdfbase\pdfmetrics.py", line 700, in getFont
    return findFontAndRegister(fontName)
  File "C:\Users\keisu\AppData\Local\Programs\Python\Python313\Lib\site-packages\reportlab\pdfbase\pdfmetrics.py", line 682, in findFontAndRegister
    face = getTypeFace(fontName)
  File "C:\Users\keisu\AppData\Local\Programs\Python\Python313\Lib\site-packages\reportlab\pdfbase\pdfmetrics.py", line 639, in getTypeFace
    return _typefaces[faceName]
           ~~~~~~~~~~^^^^^^^^^^
KeyError: 'UTF-8'
2025-06-13 15:35:12,198 [ERROR] app [C:\Users\keisu\python\app.py:1212 - create_pdf()] PDF作成中にエラー発生: user_id=4c5ba71b-b6f5-470d-aa79-5154b1227748 エラー=cannot access local variable 'max_width' where it is not associated with a value
Traceback (most recent call last):
  File "C:\Users\keisu\python\app.py", line 1151, in create_pdf
    max_width,
    ^^^^^^^^^
UnboundLocalError: cannot access local variable 'max_width' where it is not associated with a value
2025-06-16 13:06:35,896 [WARNING] app [C:\Users\keisu\python\app.py:316 - update_password_form()] パスワード更新失敗: 弱いパスワード
2025-06-16 15:39:44,315 [WARNING] app [C:\Users\keisu\python\app.py:316 - update_password_form()] パスワード更新失敗: 弱いパスワード
2025-06-16 15:40:00,449 [WARNING] app [C:\Users\keisu\python\app.py:316 - update_password_form()] パスワード更新失敗: 弱いパスワード
2025-06-17 15:52:11,316 [WARNING] app [C:\Users\keisu\python\app.py:642 - skillsheet_input()] スキルシート保存時に例外発生: user_id=4c5ba71b-b6f5-470d-aa79-5154b1227748 エラー={'code': '42P10', 'details': None, 'hint': None, 'message': 'there is no unique or exclusion constraint matching the ON CONFLICT specification'}
2025-06-17 16:26:32,955 [WARNING] app [C:\Users\keisu\python\app.py:642 - skillsheet_input()] スキルシート保存時に例外発生: user_id=4c5ba71b-b6f5-470d-aa79-5154b1227748 エラー={'code': '42P10', 'details': None, 'hint': None, 'message': 'there is no unique or exclusion constraint matching the ON CONFLICT specification'}
2025-06-17 16:43:19,006 [WARNING] app [C:\Users\keisu\python\app.py:642 - skillsheet_input()] スキルシート保存時に例外発生: user_id=4c5ba71b-b6f5-470d-aa79-5154b1227748 エラー={'code': '42P10', 'details': None, 'hint': None, 'message': 'there is no unique or exclusion constraint matching the ON CONFLICT specification'}
2025-06-17 16:45:34,356 [WARNING] app [C:\Users\keisu\python\app.py:642 - skillsheet_input()] スキルシート保存時に例外発生: user_id=4c5ba71b-b6f5-470d-aa79-5154b1227748 エラー={'code': '42P10', 'details': None, 'hint': None, 'message': 'there is no unique or exclusion constraint matching the ON CONFLICT specification'}
2025-06-17 16:45:45,691 [WARNING] app [C:\Users\keisu\python\app.py:642 - skillsheet_input()] スキルシート保存時に例外発生: user_id=4c5ba71b-b6f5-470d-aa79-5154b1227748 エラー={'code': '42P10', 'details': None, 'hint': None, 'message': 'there is no unique or exclusion constraint matching the ON CONFLICT specification'}
2025-06-17 16:48:01,143 [WARNING] app [C:\Users\keisu\python\app.py:642 - skillsheet_input()] スキルシート保存時に例外発生: user_id=4c5ba71b-b6f5-470d-aa79-5154b1227748 エラー={'code': '42P10', 'details': None, 'hint': None, 'message': 'there is no unique or exclusion constraint matching the ON CONFLICT specification'}
2025-06-17 16:53:46,257 [WARNING] app [C:\Users\keisu\python\app.py:642 - skillsheet_input()] スキルシート保存時に例外発生: user_id=4c5ba71b-b6f5-470d-aa79-5154b1227748 エラー={'code': '42P10', 'details': None, 'hint': None, 'message': 'there is no unique or exclusion constraint matching the ON CONFLICT specification'}
2025-06-18 15:36:37,189 [WARNING] app [C:\Users\keisu\python\app.py:659 - skillsheet_input()] スキルシート保存時に例外発生: user_id=4c5ba71b-b6f5-470d-aa79-5154b1227748 エラー={'code': '23505', 'details': 'Key (user_id)=(4c5ba71b-b6f5-470d-aa79-5154b1227748) already exists.', 'hint': None, 'message': 'duplicate key value violates unique constraint "custom_skills_user_id_key"'}
2025-06-18 15:41:05,060 [WARNING] app [C:\Users\keisu\python\app.py:659 - skillsheet_input()] スキルシート保存時に例外発生: user_id=4c5ba71b-b6f5-470d-aa79-5154b1227748 エラー={'code': 'PGRST204', 'details': None, 'hint': None, 'message': "Could not find the 'category' column of 'custom_skills' in the schema cache"}
2025-06-18 15:43:20,589 [WARNING] app [C:\Users\keisu\python\app.py:659 - skillsheet_input()] スキルシート保存時に例外発生: user_id=4c5ba71b-b6f5-470d-aa79-5154b1227748 エラー={'code': 'PGRST204', 'details': None, 'hint': None, 'message': "Could not find the 'category' column of 'custom_skills' in the schema cache"}
2025-06-18 15:45:23,878 [WARNING] app [C:\Users\keisu\python\app.py:659 - skillsheet_input()] スキルシート保存時に例外発生: user_id=4c5ba71b-b6f5-470d-aa79-5154b1227748 エラー={'code': 'PGRST204', 'details': None, 'hint': None, 'message': "Could not find the 'level' column of 'custom_skills' in the schema cache"}
2025-06-18 15:47:28,787 [WARNING] app [C:\Users\keisu\python\app.py:659 - skillsheet_input()] スキルシート保存時に例外発生: user_id=4c5ba71b-b6f5-470d-aa79-5154b1227748 エラー={'code': 'PGRST204', 'details': None, 'hint': None, 'message': "Could not find the 'category' column of 'custom_skills' in the schema cache"}
2025-06-18 16:27:23,044 [WARNING] app [C:\Users\keisu\python\app.py:567 - profile_input()] プロフィール保存中に例外発生: user_id=4c5ba71b-b6f5-470d-aa79-5154b1227748 エラー={'code': 'PGRST204', 'details': None, 'hint': None, 'message': "Could not find the 'certifications' column of 'profile' in the schema cache"}
